Workbook
Name SAPCrosstab1: 'WNA Calc'!$B$5:$J$8
Name SAPCrosstab1: #REF!
Name SAPCrosstab2: 'WNA Calc'!$B$31:$E$243
Name SAPCrosstab2: #REF!
Name SAPCrosstab3: SAP!$A$5:$O$65

Sheet _com.sap.ip.bi.xl.hiddensheet

Sheet WNA Calc
B10: Line | C10: Factors | D10: Nov | E10: Dec | F10: Jan | G10: Feb | H10: Mar | I10: Apr
B11: 1 | C11: ADD | D11: =SUM(SAP!I42:I53) -> 253 | E11: =SUM(SAP!J42:J53) -> 603 | F11: =SUM(SAP!K42:K53) -> 851 | G11: =SUM(SAP!L42:L53) -> 787 | H11: =SUM(SAP!M42:M53) -> 760 | I11: =SUM(SAP!N42:N53) -> 297
B12: 2 | C12: NDD | D12: =SUM(SAP!I54:I65) -> 290 | E12: =SUM(SAP!J54:J65) -> 677 | F12: =SUM(SAP!K54:K65) -> 857 | G12: =SUM(SAP!L54:L65) -> 811 | H12: =SUM(SAP!M54:M65) -> 668 | I12: =SUM(SAP!N54:N65) -> 423
B13: 3 | C13: HSF (Mcf) | D13: =0.12576/10 -> 0.012576 | E13: =D13 -> 0.012576 | F13: =E13 -> 0.012576 | G13: =F13 -> 0.012576 | H13: =G13 -> 0.012576 | I13: =H13 -> 0.012576
B14: 4 | C14: BL (Mcf) | D14: =10.556/10 -> 1.0556 | E14: =D14 -> 1.0556 | F14: =E14 -> 1.0556 | G14: =F14 -> 1.0556 | H14: =G14 -> 1.0556 | I14: =H14 -> 1.0556
B15: 5 | C15: R | D15: 1.385 | E15: =D15 -> 1.385 | F15: =E15 -> 1.385 | G15: =F15 -> 1.385 | H15: =G15 -> 1.385 | I15: =H15 -> 1.385
B16: 6 | C16: WNA Factor | D16: =(D13*(D12-D11))/(D14+(D13*D11))*D15 -> 0.15209045 | E16: =(E13*(E12-E11))/(E14+(E13*E11))*E15 -> 0.1491984 | F16: =(F13*(F12-F11))/(F14+(F13*F11))*F15 -> 0.0088882932 | G16: =(G13*(G12-G11))/(G14+(G13*G11))*G15 -> 0.038165763 | H16: =(H13*(H12-H11))/(H14+(H13*H11))*H15 -> -0.15098272 | I16: =(I13*(I12-I11))/(I14+(I13*I11))*I15 -> 0.45810645
B17: 7 | C17: Usage [1] | D17: =SUM(SAP!I18:I29) -> 5.5 | E17: =SUM(SAP!J18:J29) -> 13.1 | F17: =SUM(SAP!K18:K29) -> 19.1 | G17: =SUM(SAP!L18:L29) -> 18.2 | H17: =SUM(SAP!M18:M29) -> 15.2 | I17: =SUM(SAP!N18:N29) -> 6.4
B18: 8 | C18: WNA Adjustment | D18: =D17*D16 -> 0.83649747 | E18: =E17*E16 -> 1.954499 | F18: =F17*F16 -> 0.1697664 | G18: =G17*G16 -> 0.69461688 | H18: =H17*H16 -> -2.2949373 | I18: =I17*I16 -> 2.9318813
B19: 9 | C19: Actual Billed | D19: =SUM(SAP!I30:I41) -> 0.84 | E19: =SUM(SAP!J30:J41) -> 1.95 | F19: =SUM(SAP!K30:K41) -> 0.17 | G19: =SUM(SAP!L30:L41) -> 0.7 | H19: =SUM(SAP!M30:M41) -> -2.29 | I19: =SUM(SAP!N30:N41) -> 2.93
B20: 10 | C20: Difference | D20: =D18-D19 -> -0.003502528 | E20: =E18-E19 -> 0.0044990471 | F20: =F18-F19 -> -0.00023360064 | G20: =G18-G19 -> -0.0053831193 | H20: =H18-H19 -> -0.0049372851 | I20: =I18-I19 -> 0.0018813027
C22: Note [1] - This is an actual cycle 10 customer for the months of November through April

Sheet SAP
A5: Company Code | B5: Business Area | C5: Rate Category | D5: Billing Portion | E5: Contract Account | G5: From Date | H5: To Date|Fiscal year/period | I5: Period 02 2021 | J5: Period 03 2021 | K5: Period 04 2021 | L5: Period 05 2021 | M5: Period 06 2021 | N5: Period 07 2021 | O5: Overall Result
A6: Kentucky / Mid States | B6: Kentucky | C6: KY-RES - GEN SERVICE FIRM | D6: Portion 10 - Standard | E6: 3005159123 | F6: Base Charge Count | G6: 10/15/2020 | H6: 10/31/2020 | I6: 1 | O6: 1
G7: 11/01/2020 | H7: 11/12/2020 | I7: 0 | O7: 0
G8: 11/13/2020 | H8: 11/30/2020 | J8: 1 | O8: 1
G9: 12/01/2020 | H9: 12/14/2020 | J9: 0 | O9: 0
G10: 12/15/2020 | H10: 12/31/2020 | K10: 1 | O10: 1
G11: 01/01/2021 | H11: 01/14/2021 | K11: 0 | O11: 0
G12: 01/15/2021 | H12: 01/31/2021 | L12: 1 | O12: 1
G13: 02/01/2021 | H13: 02/11/2021 | L13: 0 | O13: 0
G14: 02/12/2021 | H14: 02/28/2021 | M14: 1 | O14: 1
G15: 03/01/2021 | H15: 03/12/2021 | M15: 0 | O15: 0
G16: 03/13/2021 | H16: 03/31/2021 | N16: 1 | O16: 1
G17: 04/01/2021 | H17: 04/15/2021 | N17: 0 | O17: 0
F18: Total Vol@MCF | G18: 10/15/2020 | H18: 10/31/2020 | I18: 3.2517 | O18: 3.2517
G19: 11/01/2020 | H19: 11/12/2020 | I19: 2.2483 | O19: 2.2483
G20: 11/13/2020 | H20: 11/30/2020 | J20: 6.3262 | O20: 6.3262
G21: 12/01/2020 | H21: 12/14/2020 | J21: 6.7738 | O21: 6.7738
G22: 12/15/2020 | H22: 12/31/2020 | K22: 10.2546 | O22: 10.2546
G23: 01/01/2021 | H23: 01/14/2021 | K23: 8.8454 | O23: 8.8454
G24: 01/15/2021 | H24: 01/31/2021 | L24: 10.3495 | O24: 10.3495
G25: 02/01/2021 | H25: 02/11/2021 | L25: 7.8505 | O25: 7.8505
G26: 02/12/2021 | H26: 02/28/2021 | M26: 11.1625 | O26: 11.1625
G27: 03/01/2021 | H27: 03/12/2021 | M27: 4.0375 | O27: 4.0375
G28: 03/13/2021 | H28: 03/31/2021 | N28: 4.0145 | O28: 4.0145
G29: 04/01/2021 | H29: 04/15/2021 | N29: 2.3855 | O29: 2.3855
F30: WNA Amount | G30: 10/15/2020 | H30: 10/31/2020 | I30: 0.5 | O30: 0.5
G31: 11/01/2020 | H31: 11/12/2020 | I31: 0.34 | O31: 0.34
G32: 11/13/2020 | H32: 11/30/2020 | J32: 0.94 | O32: 0.94
G33: 12/01/2020 | H33: 12/14/2020 | J33: 1.01 | O33: 1.01
G34: 12/15/2020 | H34: 12/31/2020 | K34: 0.09 | O34: 0.09
G35: 01/01/2021 | H35: 01/14/2021 | K35: 0.08 | O35: 0.08
G36: 01/15/2021 | H36: 01/31/2021 | L36: 0.4 | O36: 0.4
G37: 02/01/2021 | H37: 02/11/2021 | L37: 0.3 | O37: 0.3
G38: 02/12/2021 | H38: 02/28/2021 | M38: -1.68 | O38: -1.68
G39: 03/01/2021 | H39: 03/12/2021 | M39: -0.61 | O39: -0.61
G40: 03/13/2021 | H40: 03/31/2021 | N40: 1.84 | O40: 1.84
G41: 04/01/2021 | H41: 04/15/2021 | N41: 1.09 | O41: 1.09
F42: Billed Actual HDD | G42: 10/15/2020 | H42: 10/31/2020 | I42: 150 | O42: 150
G43: 11/01/2020 | H43: 11/12/2020 | I43: 103 | O43: 103
G44: 11/13/2020 | H44: 11/30/2020 | J44: 291 | O44: 291
...
